Building DAG of jobs...
Using shell: /bin/bash
Provided cores: 1
Rules claiming more threads will be scaled down.
Job counts:
	count	jobs
	1	all
	1	clustering_fit
	1	clustering_transform
	1	fa
	1	fa_sample
	1	fa_sample_plot
	1	outliers
	7

rule fa:
    input: README.md
    output: data/fa.log
    jobid: 1

Finished job 1.
1 of 7 steps (14%) done

rule outliers:
    input: data/fa.log
    output: data/outlier-removal.log
    jobid: 3

Finished job 3.
2 of 7 steps (29%) done

rule fa_sample:
    input: data/fa.log
    output: data/fa-sample.log
    jobid: 4

Finished job 4.
3 of 7 steps (43%) done

rule clustering_fit:
    input: data/outlier-removal.log
    output: data/kmeans-fit.log
    jobid: 6

Finished job 6.
4 of 7 steps (57%) done

rule fa_sample_plot:
    input: data/fa-sample.log
    output: data/fa-sample-distribution.log
    jobid: 2

Finished job 2.
5 of 7 steps (71%) done

rule clustering_transform:
    input: data/kmeans-fit.log
    output: data/kmeans-transform.log, data/kmeans-plot.log
    jobid: 5

Error in rule clustering_transform:
    jobid: 5
    output: data/kmeans-transform.log, data/kmeans-plot.log

RuleException:
CalledProcessError in line 62 of /Users/simondi/PROJECTS/target_infect_x_project/src/tix-analysis/Snakefile:
Command ' set -euo pipefail;  cat data/kmeans-fit.log > data/kmeans-transform.log data/kmeans-plot.log ' returned non-zero exit status 1.
  File "/Users/simondi/PROJECTS/target_infect_x_project/src/tix-analysis/Snakefile", line 62, in __rule_clustering_transform
  File "/Users/simondi/anaconda3/envs/py36/lib/python3.6/concurrent/futures/thread.py", line 56, in run
Removing output files of failed job clustering_transform since they might be corrupted:
data/kmeans-transform.log
Shutting down, this might take some time.
Exiting because a job execution failed. Look above for error message
Complete log: /Users/simondi/PROJECTS/target_infect_x_project/src/tix-analysis/.snakemake/log/2018-05-11T180950.291480.snakemake.log
